<!--
__author__    = "Xuanya Technology"
__email__     = "tech@xuanyatech.com"
__copyright__ = "Copyright 2025 Xuanya Technology Co. Ltd."
__date__      = "February 18, 2025"
__project__   = "Alicia_Duo_lingdong"
__version__   = "v0.3.8"
__status__    = "Product"
-->

<mujoco model="alicia_duo_mani_basic_v0_3_8">
  <compiler angle="radian" meshdir="./meshes/"/>
    <default>
        <joint type="hinge" damping="0.1" stiffness="5" armature=".007" limited="true" solimplimit="0 .99 .01"/>
    </default>
  <asset>
    <mesh name="base_link" file="base_link.STL"/>
    <mesh name="Link1" file="Link1.STL"/>
    <mesh name="Link2" file="Link2.STL"/>
    <mesh name="Link3" file="Link3.STL"/>
    <mesh name="Link4" file="Link4.STL"/>
    <mesh name="Link5" file="Link5.STL"/>
    <mesh name="Link6" file="Link6.STL"/>
    <mesh name="Grapper_finger_right" file="Grapper_finger_right.STL"/>
    <mesh name="Grapper_finger_left" file="Grapper_finger_left.STL"/>
  </asset>

  <worldbody>
    <light directional="true" pos="-0.5 0.5 3" dir="0 0 -1"/>
    <geom name="floor" type="plane" conaffinity="1" size="100 100 .2"/>
    <body name="base_link" pos="0 0 0">
      <geom type="mesh" contype="0" conaffinity="0" group="1" density="0" rgba="1 1 1 1" mesh="base_link"/>
      <geom type="mesh" rgba="1 1 1 1" mesh="base_link"/>
      <body name="Link1" pos="0 0 0.0121">
        <inertial pos="8.96172e-05 -4.16187e-11 0.0416399" quat="0.450552 0.545509 -0.450022 0.544888" mass="0.343959" diaginertia="0.00102222 0.000623566 0.00058586"/>
        <joint name="Joint1" pos="0 0 0" axis="0 0 -1" range="-2.35 2.35"/>
        <geom type="mesh" contype="0" conaffinity="0" group="1" density="0" rgba="1 1 1 1" mesh="Link1"/>
        <geom type="mesh" rgba="1 1 1 1" mesh="Link1"/>
        <body name="Link2" pos="0 -0.0005 0.090175">
          <inertial pos="0.00586755 0.000117975 0.142307" quat="0.692928 0.0170385 -0.0103054 0.720732" mass="0.136645" diaginertia="0.000112386 0.000110486 1.70144e-05"/>
          <joint name="Joint2" pos="0 0 0" axis="0 1 0" range="-1.57 1.57"/>
          <geom type="mesh" contype="0" conaffinity="0" group="1" density="0" rgba="1 1 1 1" mesh="Link2"/>
          <geom type="mesh" rgba="1 1 1 1" mesh="Link2"/>
          <body name="Link3" pos="0.029467 -0.0002 0.25252">
            <inertial pos="0.0803512 0.000209649 -0.080055" quat="0.925524 0.00261004 -0.378679 0.00113001" mass="0.0901016" diaginertia="5.11394e-05 3.94915e-05 2.89719e-05"/>
            <joint name="Joint3" pos="0 0 0" axis="0 -1 0" range="-0.78 2.35"/>
            <geom type="mesh" contype="0" conaffinity="0" group="1" density="0" rgba="1 1 1 1" mesh="Link3"/>
            <geom type="mesh" rgba="1 1 1 1" mesh="Link3"/>
            <body name="Link4" pos="0.13096 -0.009425 -0.13096">
              <inertial pos="0.0207735 -0.000464907 -0.0207735" quat="0.923879 -0.00121886 -0.382683 -0.000500728" mass="0.039525" diaginertia="6.97984e-06 6.14916e-06 3.30297e-06"/>
              <joint name="Joint4" pos="0 0 0" axis="-0.707107 0 0.707107" range="-2.35 2.35"/>
              <geom type="mesh" contype="0" conaffinity="0" group="1" density="0" rgba="1 1 1 1" mesh="Link4"/>
              <geom type="mesh" rgba="1 1 1 1" mesh="Link4"/>
              <body name="Link5" pos="0.028535 0.0002 -0.028535">
                <inertial pos="0.0427828 0.000513404 -0.000364374" quat="0.522542 0.497714 -0.496238 0.482679" mass="0.0318576" diaginertia="2.26155e-05 1.81341e-05 1.01903e-05"/>
                <joint name="Joint5" pos="0 0 0" axis="0 -1 0" range="-2.35 0.78"/>
                <geom type="mesh" contype="0" conaffinity="0" group="1" density="0" rgba="1 1 1 1" mesh="Link5"/>
                <geom type="mesh" rgba="1 1 1 1" mesh="Link5"/>
                <body name="Link6" pos="0.07345 -0.009925 0">
                  <inertial pos="0.0232448 0.00380153 0.0118694" quat="0.388533 0.391169 -0.588333 0.591518" mass="0.0777664" diaginertia="5.31535e-05 5.14686e-05 1.48909e-05"/>
                  <joint name="Joint6" pos="0 0 0" axis="-1 0 0" range="-2.35 2.35"/>
                  <geom type="mesh" contype="0" conaffinity="0" group="1" density="0" rgba="1 1 1 1" mesh="Link6"/>
                  <geom type="mesh" rgba="1 1 1 1" mesh="Link6"/>
                  <body name="Grapper_finger_right" pos="0.0633 0 0.001">
                    <inertial pos="0.00434531 0.00342289 0.00186147" quat="0.495588 0.504502 0.504 0.495838" mass="0.0292776" diaginertia="7.4779e-06 5.1431e-06 3.71026e-06"/>
                    <joint name="Grapper_finger_right" pos="0 0 0" axis="0 -1 0" type="slide" range="-0.015 0.008"/>
                    <geom type="mesh" contype="0" conaffinity="0" group="1" density="0" rgba="1 1 1 1" mesh="Grapper_finger_right"/>
                    <geom type="mesh" rgba="1 1 1 1" mesh="Grapper_finger_right"/>
                  </body>
                  <body name="Grapper_finger_left" pos="0.0633 0 0.001">
                    <inertial pos="0.0043824 -0.00181839 0.00185898" quat="0.495722 0.504483 0.503869 0.495855" mass="0.029207" diaginertia="7.44179e-06 5.11035e-06 3.70621e-06"/>
                    <joint name="Grapper_finger_left" pos="0 0 0" axis="0 1 0" type="slide" range="-0.015 0.008"/>
                    <geom type="mesh" contype="0" conaffinity="0" group="1" density="0" rgba="1 1 1 1" mesh="Grapper_finger_left"/>
                    <geom type="mesh" rgba="1 1 1 1" mesh="Grapper_finger_left"/>
                  </body>
                </body>
              </body>
            </body>
          </body>
        </body>
      </body>
            </body>
  </worldbody>
  <contact>
    <exclude body1="base_link" body2="Link1"/>
  </contact>
</mujoco>
