<mujoco model="alicia_D_v5_4">
  <compiler angle="radian" meshdir="../meshes/"/>
  <default>
      <joint armature="0.001" damping="0.01" frictionloss="0.001" limited="true" margin="0.001" type="hinge"/>
      <geom material="black"/>
  </default>
  <asset>
    <mesh name="base_link" file="base_link.STL"/>
    <mesh name="Link1" file="Link1.STL"/>
    <mesh name="Link2" file="Link2.STL"/>
    <mesh name="Link3" file="Link3.STL"/>
    <mesh name="Link4" file="Link4.STL"/>
    <mesh name="Link5" file="Link5.STL"/>
    <mesh name="Link6" file="Link6.STL"/>
    <mesh name="Grasp_base" file="Grasp_base.STL"/>
    <mesh name="Link7" file="Link7.STL"/>
    <mesh name="Link8" file="Link8.STL"/>
    <texture builtin="gradient" height="100" rgb1=".4 .5 .6" rgb2="0 0 0" type="skybox" width="100"/>
    <texture builtin="checker" height="100" name="texplane" rgb1="1 1 1" rgb2=".8 .9 1" type="2d"
              width="100"/>
    <material name="MatPlane" reflectance="0.5" texrepeat="1 1" texture="texplane" texuniform="true"/>
    <material name="white" rgba="1 1 1 1" shininess="0.5" specular="0.1"/>
    <material name="black" rgba="0.25 0.25 0.25 1" shininess="0.2" specular="0.05"/>
    <material name="invisible" rgba="1 1 1 0" shininess="0" specular="0"/>
  </asset>

  <worldbody>
    <geom conaffinity="1" condim="3" contype="1" friction="1 .1 .1" group="2" material="MatPlane" name="floor"
          pos="0 0 0" rgba="0.8 0.9 0.8 1" size="500 500 0.125" type="plane"/>
    <light castshadow="false" cutoff="100" diffuse="1 1 1" dir="-0 0 -1.3" directional="true" exponent="1"
            pos="0 0 1.3" specular=".1 .1 .1"/>
    <body name="base_link" pos="0 0 0" quat="1 0 0 0">
      <geom type="mesh" contype="0" conaffinity="0" group="1" density="0"  mesh="base_link"/>
      <geom type="mesh"  mesh="base_link"/>
      <body name="Link1" pos="0 0 0.1445">
        <inertial pos="-6.25858e-05 7.92213e-05 -0.0125708" quat="0.495669 0.502153 -0.500685 0.501467" mass="0.203076" diaginertia="0.000304859 0.000235909 0.00013145"/>
        <joint name="Joint1" pos="0 0 0" axis="0 0 1" range="-2.16 2.16" actuatorfrcrange="-12 12"/>
        <geom type="mesh" contype="0" conaffinity="0" group="1" density="0"  mesh="Link1"/>
        <geom type="mesh"  mesh="Link1"/>
        <body name="Link2" pos="0 0 0.025106" quat="0.499998 0.5 -0.5 0.500002">
          <inertial pos="0.152521 0.0012105 -2.60951e-05" quat="0.559299 0.425653 0.430416 0.566345" mass="0.228751" diaginertia="0.000222417 0.000139383 0.000127226"/>
          <joint name="Joint2" pos="0 0 0" axis="0 0 -1" range="-1.57 1.57" actuatorfrcrange="-12 12"/>
          <geom type="mesh" contype="0" conaffinity="0" group="1" density="0"  mesh="Link2"/>
          <geom type="mesh"  mesh="Link2"/>
          <body name="Link3" pos="0.22367 0.022494 -5e-05" quat="0.382681 0 0 0.923881">
            <inertial pos="0.059121 -0.00292884 -0.00020687" quat="0.0100113 0.743852 -0.0277331 0.667694" mass="0.0902085" diaginertia="7.6497e-05 7.15699e-05 2.89138e-05"/>
            <joint name="Joint3" pos="0 0 0" axis="0 0 -1" range="-0.5 2.35619" actuatorfrcrange="-12 12"/>
            <geom type="mesh" contype="0" conaffinity="0" group="1" density="0"  mesh="Link3"/>
            <geom type="mesh"  mesh="Link3"/>
            <body name="Link4" pos="0.0988 0.00211 -0.0001" quat="0.499998 0.5 0.500002 0.5">
              <inertial pos="-0.000205267 0.000325243 0.0643236" quat="0.999753 -0.018319 -0.004056 -0.0119026" mass="0.0791975" diaginertia="2.47732e-05 2.46755e-05 1.52211e-05"/>
              <joint name="Joint4" pos="0 0 0" axis="0 0 -1" range="-3.14 3.14" actuatorfrcrange="-12 12"/>
              <geom type="mesh" contype="0" conaffinity="0" group="1" density="0"  mesh="Link4"/>
              <geom type="mesh"  mesh="Link4"/>
              <body name="Link5" pos="0 -0.0007 0.12011" quat="0.707105 -0.707108 0 0">
                <inertial pos="-0.0151916 -0.0355776 0.00100363" quat="0.477111 0.435591 0.530724 0.548596" mass="0.0472227" diaginertia="1.9048e-05 1.40597e-05 1.18222e-05"/>
                <joint name="Joint5" pos="0 0 0" axis="0 0 -1" range="-1.57 1.5" actuatorfrcrange="-12 12"/>
                <geom type="mesh" contype="0" conaffinity="0" group="1" density="0"  mesh="Link5"/>
                <geom type="mesh"  mesh="Link5"/>
                <body name="Link6" pos="-0.0038938 -0.0573 0.0008" quat="0.707105 0.707108 0 0">
                  <inertial pos="-0.0183097 0.00085798 0.0337757" quat="0.574888 0.563521 -0.415241 0.423701" mass="0.136803" diaginertia="8.05186e-05 7.30959e-05 3.11449e-05"/>
                  <joint name="Joint6" pos="0 0 0" axis="0 0 -1" range="-3.14 3.14" actuatorfrcrange="-12 12"/>
                  <geom type="mesh" contype="0" conaffinity="0" group="1" density="0" mesh="Link6"/>
                  <geom type="mesh"  mesh="Link6"/>
                  <geom type="mesh" contype="0" conaffinity="0" group="1" density="0"  mesh="Grasp_base"/>
                  <geom type="mesh"  mesh="Grasp_base"/>
                  <geom size="0.005" pos="0.00275 0.0008332 0.13779" contype="0" conaffinity="0" group="1" density="0" rgba="0 1 0 1"/>
                  <body name="Link7" pos="0.00275 -0.0011661 0.13779" quat="0.716133 0.697964 0 0">
                    <inertial pos="0.00110741 -0.0505406 0.00928375" quat="0.48495 0.518462 -0.407827 0.574194" mass="0.0243493" diaginertia="1.23445e-05 9.71575e-06 3.92783e-06"/>
                    <joint name="left_finger" pos="0 0 0" axis="0 0 -1" type="slide" range="-0.025 0" actuatorfrcrange="-5 5"/>
                    <geom type="mesh" contype="0" conaffinity="0" group="1" density="0"  mesh="Link7"/>
                    <geom type="mesh"  mesh="Link7"/>
                  </body>
                  <body name="Link8" pos="0.00275 0.0028325 0.13768" quat="0.697961 -0.716136 0 0">
                    <inertial pos="0.00109597 0.0498869 0.0118635" quat="0.505733 0.498237 -0.58443 0.392982" mass="0.0243228" diaginertia="1.23098e-05 9.68264e-06 3.925e-06"/>
                    <joint name="right_finger" pos="0 0 0" axis="0 0 1" type="slide" range="0 0.025" actuatorfrcrange="-5 5"/>
                    <geom type="mesh" contype="0" conaffinity="0" group="1" density="0"  mesh="Link8"/>
                    <geom type="mesh"  mesh="Link8"/>
                  </body>
                </body>
              </body>
            </body>
          </body>
        </body>
      </body>
    </body>
  </worldbody>
  <actuator>
    <motor joint="Joint1"  gear="100"/>
    <motor joint="Joint2"  gear="100"/>
    <motor joint="Joint3"  gear="100"/>
    <motor joint="Joint4" gear="100"/>
    <motor joint="Joint5"  gear="100"/>
    <motor joint="Joint6" gear="100"/>
    <position joint="left_finger"/>
    <position joint="right_finger"/>
  </actuator>
  <contact>
    <exclude body1="base_link" body2="Link1"/>
    <exclude body1="Link1" body2="Link2"/>
    <exclude body1="Link2" body2="Link3"/>
    <exclude body1="Link3" body2="Link4"/>
    <exclude body1="Link4" body2="Link5"/>
    <exclude body1="Link5" body2="Link6"/>
    <exclude body1="Link6" body2="Link7"/>
    <exclude body1="Link6" body2="Link8"/>
  </contact>
</mujoco>
