<mujoco model="Alicia_duo_mani_basic_v0_3">
  <compiler angle="radian" autolimits="true" meshdir="./meshes/" />

  <asset>
    <mesh name="base_link" file="base_link.STL"/>
    <mesh name="link1" file="link1.STL"/>
    <mesh name="link2" file="link2.STL"/>
    <mesh name="link3" file="link3.STL"/>
    <mesh name="link4" file="link4.STL"/>
    <mesh name="link5" file="link5.STL"/>
    <mesh name="link6" file="link6.STL"/>
  </asset>

  <worldbody>
    <geom type="mesh" contype="0" conaffinity="0" group="1" density="0" rgba="1 1 1 1" mesh="base_link"/>
    <geom type="mesh" rgba="1 1 1 1" mesh="base_link"/>
    <body name="link1" pos="0 0 0.0121" quat="0.110627 0.110628 0.698401 0.698398">
      <inertial pos="-6.9961e-05 0.048527 2.2732e-05" quat="0.684373 0.176285 0.17622 0.685203" mass="0.41903" diaginertia="0.0010271 0.00063616 0.000598359"/>
      <joint name="Joint1" pos="0 0 0" axis="0 1 0" range="-3.14 3.14" actuatorfrcrange="-12 12"/>
      <geom type="mesh" contype="0" conaffinity="0" group="1" density="0" rgba="1 1 1 1" mesh="link1"/>
      <geom type="mesh" rgba="1 1 1 1" mesh="link1"/>
      <body name="link2" pos="-4.1379e-05 0.09015 1.3445e-05" quat="-0.293787 -0.509081 -0.404377 0.700718">
        <inertial pos="0.000382025 -0.126209 -0.066003" quat="0.504313 0.863081 -0.00734649 0.0265785" mass="0.136645" diaginertia="0.000112386 0.000110486 1.70144e-05"/>
        <joint name="Joint2" pos="0 0 0" axis="-1 0 0" range="-2.04 1.04" actuatorfrcrange="-12 12"/>
        <geom type="mesh" contype="0" conaffinity="0" group="1" density="0" rgba="1 1 1 1" mesh="link2"/>
        <geom type="mesh" rgba="1 1 1 1" mesh="link2"/>
        <body name="link3" pos="0 -0.23348 -0.10057" quat="0.057632 -0.704754 0.0576372 -0.704754">
          <inertial pos="0.0976602 -0.0340665 0.000539534" quat="0.820951 -0.00484652 -0.00330337 0.570968" mass="0.101796" diaginertia="3.9157e-05 2.84813e-05 2.63741e-05"/>
          <joint name="Joint3" pos="0 0 0" axis="0 0 1" range="-0.87 2.29" actuatorfrcrange="-12 12"/>
          <geom type="mesh" contype="0" conaffinity="0" group="1" density="0" rgba="1 1 1 1" mesh="link3"/>
          <geom type="mesh" rgba="1 1 1 1" mesh="link3"/>
          <body name="link4" pos="0.14979 -0.05255 0.010125" quat="0.052384 0.812438 0.575968 -0.0738971">
            <inertial pos="-0.000154084 0.0251967 -0.000427933" quat="0.697499 0.695649 0.121751 -0.121428" mass="0.0404008" diaginertia="7.00265e-06 6.17197e-06 3.34646e-06"/>
            <joint name="Joint4" pos="0 0 0" axis="0 -1 0" range="-3.14 3.14" actuatorfrcrange="-12 12"/>
            <geom type="mesh" contype="0" conaffinity="0" group="1" density="0" rgba="1 1 1 1" mesh="link4"/>
            <geom type="mesh" rgba="1 1 1 1" mesh="link4"/>
            <body name="link5" pos="0 0.036819 0" quat="0.0927897 0.829326 -0.531653 -0.144755">
              <inertial pos="-0.0153767 -0.038488 -9.71556e-05" quat="0.978921 -0.0130744 0.00729506 -0.203689" mass="0.0658419" diaginertia="2.73581e-05 2.19473e-05 1.24661e-05"/>
              <joint name="Joint5" pos="0 0 0" axis="0 0 -1" range="-0.81 2.1" actuatorfrcrange="-12 12"/>
              <geom type="mesh" contype="0" conaffinity="0" group="1" density="0" rgba="1 1 1 1" mesh="link5"/>
              <geom type="mesh" rgba="1 1 1 1" mesh="link5"/>
              <body name="link6" pos="-0.025325 -0.064179 0.009725" quat="0.186404 0.0633797 -0.012051 0.980353">
                <inertial pos="0 0.00405694 0" quat="0.707107 0 0 0.707107" mass="0.000875817" diaginertia="4.34941e-08 2.28167e-08 2.28167e-08"/>
                <joint name="Joint6" pos="0 0 0" axis="0 -1 0" range="-3.14 3.14" actuatorfrcrange="-12 12"/>
                <geom type="mesh" contype="0" conaffinity="0" group="1" density="0" rgba="1 1 1 1" mesh="link6"/>
                <geom type="mesh" rgba="1 1 1 1" mesh="link6"/>
              </body>
            </body>
          </body>
        </body>
      </body>
    </body>
  </worldbody>
</mujoco>
